<?xml version="1.0" ?><!-- =================================================================================== --><!-- |    This document was autogenerated by xacro from /home/callum/Documents/eit/robot-arm-sim/ros2_ws/install/robot_arm/share/robot_arm/urdf/robot_arm.urdf.xacro | --><!-- |    EDITING THIS FILE BY HAND IS NOT RECOMMENDED                                 | --><!-- =================================================================================== --><robot name="robot_arm"><!-- Base Link --><link name="base_link"><inertial><mass value="5.0"/><inertia ixx="0.1" ixy="0.0" ixz="0.0" iyy="0.1" iyz="0.0" izz="0.1"/></inertial><collision><geometry><cylinder length="10" radius="5"/></geometry></collision><visual><geometry><cylinder length="10" radius="5"/></geometry><material name="blue"><color rgba="0 0 1 1"/></material></visual></link><!-- Fix Base to World --><joint name="fixed_joint" type="fixed"><parent link="world"/><child link="base_link"/><origin xyz="0 0 0"/></joint><!-- Revolute Joint 1 --><joint name="joint_1" type="revolute"><parent link="base_link"/><child link="link_1"/><origin xyz="0 0 5.0"/><axis xyz="0 0 1"/><limit effort="10" lower="-1.57" upper="1.57" velocity="1"/></joint><!-- Link 1 --><link name="link_1"><inertial><mass value="2.0"/><inertia ixx="0.02" ixy="0.0" ixz="0.0" iyy="0.02" iyz="0.0" izz="0.02"/></inertial><collision><geometry><cylinder length="1" radius="1"/></geometry></collision><visual><geometry><cylinder length="1" radius="1"/></geometry><material name="red"><color rgba="1 0 0 1"/></material></visual></link><!-- Revolute Joint 2 --><joint name="joint_2" type="revolute"><parent link="link_1"/><child link="link_2"/><origin xyz="0 0 1.0"/><axis xyz="0 0 1"/><limit effort="10" lower="-1.57" upper="1.57" velocity="1"/></joint><!-- Link 2 --><link name="link_2"><inertial><mass value="1.5"/><inertia ixx="0.015" ixy="0.0" ixz="0.0" iyy="0.015" iyz="0.0" izz="0.015"/></inertial><collision><geometry><cylinder length="1" radius="1"/></geometry></collision><visual><geometry><cylinder length="1" radius="1"/></geometry><material name="green"><color rgba="0 1 0 1"/></material></visual></link></robot>